<mujoco model="ur5e scene">
  <compiler angle="radian" meshdir="meshes/" autolimits="true"/>
  
  <option integrator="implicitfast" timestep="0.001"/>

  <extension>
    <plugin plugin="mujoco.elasticity.solid"/>
  </extension>

  <statistic center="0.3 0 0.4" extent="0.8"/>

  <visual>
    <headlight diffuse="0.6 0.6 0.6" ambient="0.1 0.1 0.1" specular="0 0 0"/>
    <rgba haze="0.15 0.25 0.35 1"/>
    <global azimuth="120" elevation="-20"/>
  </visual>

  <asset>
    <texture type="skybox" builtin="gradient" rgb1="0.3 0.5 0.7" rgb2="0 0 0" width="512" height="3072"/>
    <texture type="2d" name="groundplane" builtin="checker" mark="edge" rgb1="0.2 0.3 0.4" rgb2="0.1 0.2 0.3"
      markrgb="0.8 0.8 0.8" width="300" height="300"/>
    <material name="groundplane" texture="groundplane" texuniform="true" texrepeat="5 5" reflectance="0.2"/>
  </asset>

  <default>
    <default class="ur5e">
      <material specular="0.5" shininess="0.25"/>
      <joint axis="0 1 0" range="-6.28319 6.28319" armature="0.1"/>
      <!-- position actuators -->
      <!-- <general gaintype="fixed" biastype="affine" ctrlrange="-6.2831 6.2831" gainprm="2000"
      biasprm="0 -2000 -400"
        forcerange="-150 150"/> -->
      <default class="size3">
        <default class="size3_limited">
          <joint range="-3.1415 3.1415" />
          <!-- <general ctrlrange="-3.1415 3.1415"/> -->
        </default>
      </default>
      <default class="size1">
        <general gainprm="500" biasprm="0 -500 -100" forcerange="-28 28"/>
      </default>
      <default class="visual">
        <geom type="mesh" contype="0" conaffinity="0" group="2"/>
      </default>
      <default class="collision">
        <geom type="capsule" group="3"/>
        <default class="eef_collision">
          <geom type="cylinder"/>
        </default>
        <default class="us_probe_collision">
          <geom type="mesh"/>
        </default>
      </default>
      <site size="0.001" rgba="0.5 0.5 0.5 0.3" group="4"/>
    </default>
  </default>

  <asset>
    <material class="ur5e" name="black" rgba="0.033 0.033 0.033 1"/>
    <material class="ur5e" name="jointgray" rgba="0.278 0.278 0.278 1"/>
    <material class="ur5e" name="linkgray" rgba="0.82 0.82 0.82 1"/>
    <material class="ur5e" name="urblue" rgba="0.49 0.678 0.8 1"/>

    <mesh file="ur5e/base_0.obj"/>
    <mesh file="ur5e/base_1.obj"/>
    <mesh file="ur5e/shoulder_0.obj"/>
    <mesh file="ur5e/shoulder_1.obj"/>
    <mesh file="ur5e/shoulder_2.obj"/>
    <mesh file="ur5e/upperarm_0.obj"/>
    <mesh file="ur5e/upperarm_1.obj"/>
    <mesh file="ur5e/upperarm_2.obj"/>
    <mesh file="ur5e/upperarm_3.obj"/>
    <mesh file="ur5e/forearm_0.obj"/>
    <mesh file="ur5e/forearm_1.obj"/>
    <mesh file="ur5e/forearm_2.obj"/>
    <mesh file="ur5e/forearm_3.obj"/>
    <mesh file="ur5e/wrist1_0.obj"/>
    <mesh file="ur5e/wrist1_1.obj"/>
    <mesh file="ur5e/wrist1_2.obj"/>
    <mesh file="ur5e/wrist2_0.obj"/>
    <mesh file="ur5e/wrist2_1.obj"/>
    <mesh file="ur5e/wrist2_2.obj"/>
    <mesh file="ur5e/wrist3.obj"/>
    <mesh file="ur5e/end_effector.stl"/>
    <mesh file="ur5e/HD3L15.stl" scale="0.001 0.001 0.001"/> <!--Scale from mm to m due to STL units-->
    <mesh file="ur5e/us_probe.stl" /> 
    <mesh file="phantom/phantom.stl" /> 
  </asset>

  <worldbody>
    <light pos="0 0 1.5" dir="0 0 -1" directional="true"/>
    <geom name="floor" size="0 0 0.05" type="plane" material="groundplane"/>
    <body name="base" quat="1 0 0 1" childclass="ur5e">
      <inertial mass="4.0" pos="0 0 0" diaginertia="0.00443333156 0.00443333156 0.0072"/>
      <geom mesh="base_0" material="black" class="visual"/>
      <geom mesh="base_1" material="jointgray" class="visual"/>
      <body name="shoulder_link" pos="0 0 0.163">
        <inertial mass="3.7" pos="0 0 0" diaginertia="0.0102675 0.0102675 0.00666"/>
        <joint name="shoulder_pan_joint" class="size3" axis="0 0 1"/>
        <geom mesh="shoulder_0" material="urblue" class="visual"/>
        <geom mesh="shoulder_1" material="black" class="visual"/>
        <geom mesh="shoulder_2" material="jointgray" class="visual"/>
        <geom class="collision" size="0.06 0.06" pos="0 0 -0.04"/>
        <body name="upper_arm_link" pos="0 0.138 0" quat="1 0 1 0">
          <inertial mass="8.393" pos="0 0 0.2125" diaginertia="0.133886 0.133886 0.0151074"/>
          <joint name="shoulder_lift_joint" class="size3"/>
          <geom mesh="upperarm_0" material="linkgray" class="visual"/>
          <geom mesh="upperarm_1" material="black" class="visual"/>
          <geom mesh="upperarm_2" material="jointgray" class="visual"/>
          <geom mesh="upperarm_3" material="urblue" class="visual"/>
          <geom class="collision" pos="0 -0.04 0" quat="1 1 0 0" size="0.06 0.06"/>
          <geom class="collision" size="0.05 0.2" pos="0 0 0.2"/>
          <body name="forearm_link" pos="0 -0.131 0.425">
            <inertial mass="2.275" pos="0 0 0.196" diaginertia="0.0311796 0.0311796 0.004095"/>
            <joint name="elbow_joint" class="size3_limited"/>
            <geom mesh="forearm_0" material="urblue" class="visual"/>
            <geom mesh="forearm_1" material="linkgray" class="visual"/>
            <geom mesh="forearm_2" material="black" class="visual"/>
            <geom mesh="forearm_3" material="jointgray" class="visual"/>
            <geom class="collision" pos="0 0.08 0" quat="1 1 0 0" size="0.055 0.06"/>
            <geom class="collision" size="0.038 0.19" pos="0 0 0.2"/>
            <body name="wrist_1_link" pos="0 0 0.392" quat="1 0 1 0">
              <inertial mass="1.219" pos="0 0.127 0" diaginertia="0.0025599 0.0025599 0.0021942"/>
              <joint name="wrist_1_joint" class="size1"/>
              <geom mesh="wrist1_0" material="black" class="visual"/>
              <geom mesh="wrist1_1" material="urblue" class="visual"/>
              <geom mesh="wrist1_2" material="jointgray" class="visual"/>
              <geom class="collision" pos="0 0.05 0" quat="1 1 0 0" size="0.04 0.07"/>
              <body name="wrist_2_link" pos="0 0.127 0">
                <inertial mass="1.219" pos="0 0 0.1" diaginertia="0.0025599 0.0025599 0.0021942"/>
                <joint name="wrist_2_joint" axis="0 0 1" class="size1"/>
                <geom mesh="wrist2_0" material="black" class="visual"/>
                <geom mesh="wrist2_1" material="urblue" class="visual"/>
                <geom mesh="wrist2_2" material="jointgray" class="visual"/>
                <geom class="collision" size="0.04 0.06" pos="0 0 0.04"/>
                <geom class="collision" pos="0 0.02 0.1" quat="1 1 0 0" size="0.04 0.04"/>
                <body name="wrist_3_link" pos="0 0 0.1">
                  <inertial mass="0.1889" pos="0 0.0771683 0" quat="1 0 0 1"
                    diaginertia="0.000132134 9.90863e-05 9.90863e-05"/>
                  <joint name="wrist_3_joint" class="size1"/>
                  <geom material="linkgray" mesh="wrist3" class="visual"/>
                  <geom class="eef_collision" pos="0 0.08 0" quat="1 1 0 0" size="0.04 0.02"/>
                  <site name="eef_site" pos="0 0.1 0" quat="1 0 0 1"/>
                  <!--body name="end_effector" pos="0 0.1 0" quat="1 1 0 0">
                    <inertial mass="0.05" pos="0 0.0771683 0" quat="1 0 0 1"
                      diaginertia="0.000132134 9.90863e-05 9.90863e-05"/>
                    <geom material="jointgray" mesh="HD3L15" class="visual"/>
                    <geom class="eef_collision" pos="0 0 -0.0512" quat="1 0 0 1" size="0.02 0.0512"/>
                    <site name="eef_site" pos="0 0 -0.1024" quat="1 0 0 1"/>
                  </body>
                  -->
                  <body name="end_effector" pos="0 0.098 0" quat="1 0 0 0">
                    <inertial mass="0.325" pos="0 0.07675 0"/>
                    <geom material="jointgray" mesh="us_probe" class="visual"/>
                    <geom class="us_probe_collision" mesh="us_probe"/>
                    <site name="tcp_site" pos="0 0.15175 0" quat="1 0 0 1"/>
                  </body>
                </body>
              </body>
            </body>
          </body>
        </body>
      </body>
    </body>
  </worldbody>

  <actuator>
    <motor class="size3" name="shoulder_pan" joint="shoulder_pan_joint"/>
    <motor class="size3" name="shoulder_lift" joint="shoulder_lift_joint"/>
    <motor class="size3_limited" name="elbow" joint="elbow_joint"/>
    <motor class="size1" name="wrist_1" joint="wrist_1_joint"/>
    <motor class="size1" name="wrist_2" joint="wrist_2_joint"/>
    <motor class="size1" name="wrist_3" joint="wrist_3_joint"/>
  </actuator>

  <sensor>
    <force name="eef_force" site="eef_site" cutoff="50" />
    <torque name="eef_torque" site="eef_site" cutoff="10" />
  </sensor>

  <worldbody>
    <flexcomp type="grid" count="10 9 4" spacing=".02 .02 .02" pos=".5 .5 .03"
              radius=".0001" rgba=".33 .31 0.28 1" name="softbody" dim="3" mass="1">
        <pin id="0 32 324 356" range="1 1 1 1 1 1 1 1"/> <!--pin the lower 4 corners in place-->
        <contact condim="3" solref="0.01 1" solimp=".95 .99 .0001" selfcollide="none"/>
        <edge damping="1"/>
        <plugin plugin="mujoco.elasticity.solid">
          <config key="poisson" value="0.1"/>
          <config key="young" value="5e4"/><!--15 kPa-->
        </plugin>
    </flexcomp>
  </worldbody>
</mujoco>
